

==> WARNING: A newer version of conda exists. <==
  current version: 4.10.3
  latest version: 4.11.0

Please update conda by running

    $ conda update -n base -c defaults conda




==> WARNING: A newer version of conda exists. <==
  current version: 4.10.3
  latest version: 4.11.0

Please update conda by running

    $ conda update -n base -c defaults conda



# >>>>>>>>>>>>>>>>>>>>>> ERROR REPORT <<<<<<<<<<<<<<<<<<<<<<

    Traceback (most recent call last):
      File "/home1/08213/pkedia/anaconda3/lib/python3.9/site-packages/conda/core/package_cache_data.py", line 301, in _make_single_record
        repodata_record = read_repodata_json(extracted_package_dir)
      File "/home1/08213/pkedia/anaconda3/lib/python3.9/site-packages/conda/gateways/disk/read.py", line 120, in read_repodata_json
        with open(join(extracted_package_directory, 'info', 'repodata_record.json')) as fi:
      File "/home1/08213/pkedia/anaconda3/lib/python3.9/site-packages/conda/common/compat.py", line 179, in open
        return io_open(file, str(mode), buffering=buffering,
    FileNotFoundError: [Errno 2] No such file or directory: '/home1/08213/pkedia/anaconda3/pkgs/rdkit-2019.03.1.0-py36hc20afe1_1/info/repodata_record.json'
    
    During handling of the above exception, another exception occurred:
    
    Traceback (most recent call last):
      File "/home1/08213/pkedia/anaconda3/lib/python3.9/site-packages/conda/exceptions.py", line 1079, in __call__
        return func(*args, **kwargs)
      File "/home1/08213/pkedia/anaconda3/lib/python3.9/site-packages/conda_env/cli/main.py", line 80, in do_call
        exit_code = getattr(module, func_name)(args, parser)
      File "/home1/08213/pkedia/anaconda3/lib/python3.9/site-packages/conda_env/cli/main_update.py", line 123, in execute
        result[installer_type] = installer.install(prefix, specs, args, env)
      File "/home1/08213/pkedia/anaconda3/lib/python3.9/site-packages/conda_env/installers/conda.py", line 58, in install
        unlink_link_transaction.download_and_extract()
      File "/home1/08213/pkedia/anaconda3/lib/python3.9/site-packages/conda/core/link.py", line 195, in download_and_extract
        self._pfe.execute()
      File "/home1/08213/pkedia/anaconda3/lib/python3.9/site-packages/conda/core/package_cache_data.py", line 627, in execute
        self.prepare()
      File "/home1/08213/pkedia/anaconda3/lib/python3.9/site-packages/conda/common/io.py", line 88, in decorated
        return f(*args, **kwds)
      File "/home1/08213/pkedia/anaconda3/lib/python3.9/site-packages/conda/core/package_cache_data.py", line 611, in prepare
        self.paired_actions.update((prec, self.make_actions_for_record(prec))
      File "/home1/08213/pkedia/anaconda3/lib/python3.9/site-packages/conda/core/package_cache_data.py", line 611, in <genexpr>
        self.paired_actions.update((prec, self.make_actions_for_record(prec))
      File "/home1/08213/pkedia/anaconda3/lib/python3.9/site-packages/conda/core/package_cache_data.py", line 499, in make_actions_for_record
        extracted_pcrec = next((
      File "/home1/08213/pkedia/anaconda3/lib/python3.9/site-packages/conda/core/package_cache_data.py", line 499, in <genexpr>
        extracted_pcrec = next((
      File "/home1/08213/pkedia/anaconda3/lib/python3.9/site-packages/conda/core/package_cache_data.py", line 500, in <genexpr>
        pcrec for pcrec in concat(PackageCacheData(pkgs_dir).query(pref_or_spec)
      File "/home1/08213/pkedia/anaconda3/lib/python3.9/site-packages/conda/core/package_cache_data.py", line 130, in query
        return (pcrec for pcrec in itervalues(self._package_cache_records) if pcrec == param)
      File "/home1/08213/pkedia/anaconda3/lib/python3.9/site-packages/conda/core/package_cache_data.py", line 244, in _package_cache_records
        self.load()
      File "/home1/08213/pkedia/anaconda3/lib/python3.9/site-packages/conda/core/package_cache_data.py", line 96, in load
        package_cache_record = self._make_single_record(base_name)
      File "/home1/08213/pkedia/anaconda3/lib/python3.9/site-packages/conda/core/package_cache_data.py", line 392, in _make_single_record
        write_as_json_to_file(repodata_record_path, repodata_record)
      File "/home1/08213/pkedia/anaconda3/lib/python3.9/site-packages/conda/gateways/disk/create.py", line 111, in write_as_json_to_file
        with codecs.open(file_path, mode='wb', encoding='utf-8') as fo:
      File "/home1/08213/pkedia/anaconda3/lib/python3.9/codecs.py", line 905, in open
        file = builtins.open(filename, mode, buffering)
    OSError: [Errno 122] Disk quota exceeded: '/home1/08213/pkedia/anaconda3/pkgs/rdkit-2019.03.1.0-py36hc20afe1_1/info/repodata_record.json'

`$ /home1/08213/pkedia/anaconda3/bin/conda-env update --file environment.yml`

  environment variables:
                 CIO_TEST=<not set>
            COMPILER_PATH=/opt/apps/xalt/xalt/bin
  CONDA_AUTO_UPDATE_CONDA=false
        CONDA_DEFAULT_ENV=janus
                CONDA_EXE=/home1/08213/pkedia/anaconda3/bin/conda
             CONDA_PREFIX=/home1/08213/pkedia/anaconda3/envs/janus
    CONDA_PROMPT_MODIFIER=(janus)
         CONDA_PYTHON_EXE=/home1/08213/pkedia/anaconda3/bin/python
               CONDA_ROOT=/home1/08213/pkedia/anaconda3
              CONDA_SHLVL=1
                    CPATH=/opt/intel/compilers_and_libraries_2018.2.199/linux/pstl/include:/opt/
                          intel/compilers_and_libraries_2018.2.199/linux/daal/include:/opt/intel
                          /compilers_and_libraries_2018.2.199/linux/tbb/include:/opt/intel/compi
                          lers_and_libraries_2018.2.199/linux/mkl/include:/opt/intel/compilers_a
                          nd_libraries_2018.2.199/linux/ipp/include
           CURL_CA_BUNDLE=<not set>
                    FPATH=/opt/apps/lmod/lmod/init/ksh_funcs
            GIT_EXEC_PATH=/opt/apps/git/2.24.1/libexec/git-core
          LD_LIBRARY_PATH=/opt/apps/intel18/python2/2.7.15/lib:/opt/apps/libfabric/1.7.0/lib:/op
                          t/intel/compilers_and_libraries_2018.2.199/linux/mpi/intel64/lib:/opt/
                          intel/debugger_2018/libipt/intel64/lib:/opt/intel/debugger_2018/iga/li
                          b:/opt/intel/compilers_and_libraries_2018.2.199/linux/daal/../tbb/lib/
                          intel64_lin/gcc4.4:/opt/intel/compilers_and_libraries_2018.2.199/linux
                          /daal/lib/intel64_lin:/opt/intel/compilers_and_libraries_2018.2.199/li
                          nux/tbb/lib/intel64/gcc4.7:/opt/intel/compilers_and_libraries_2018.2.1
                          99/linux/mkl/lib/intel64_lin:/opt/intel/compilers_and_libraries_2018.2
                          .199/linux/compiler/lib/intel64_lin:/opt/intel/compilers_and_libraries
                          _2018.2.199/linux/ipp/lib/intel64:/opt/intel/compilers_and_libraries_2
                          018.2.199/linux/compiler/lib/intel64:/opt/apps/gcc/6.3.0/lib64:/opt/ap
                          ps/gcc/6.3.0/lib
             LIBRARY_PATH=/opt/intel/compilers_and_libraries_2018.2.199/linux/daal/../tbb/lib/in
                          tel64_lin/gcc4.4:/opt/intel/compilers_and_libraries_2018.2.199/linux/d
                          aal/lib/intel64_lin:/opt/intel/compilers_and_libraries_2018.2.199/linu
                          x/tbb/lib/intel64/gcc4.7:/opt/intel/compilers_and_libraries_2018.2.199
                          /linux/mkl/lib/intel64_lin:/opt/intel/compilers_and_libraries_2018.2.1
                          99/linux/compiler/lib/intel64_lin:/opt/intel/compilers_and_libraries_2
                          018.2.199/linux/ipp/lib/intel64
                  MANPATH=/usr/local/man:/usr/share/man:/usr/X11R6/man:/usr/kerberos/man:/usr/ma
                          n:/opt/apps/intel18/python2/2.7.15/share/man:/opt/apps/intel18/python2
                          /2.7.15/man:/opt/apps/git/2.24.1/share/man:/opt/apps/libfabric/1.7.0/s
                          hare/man:/opt/intel/compilers_and_libraries_2018.2.199/linux/mpi/man:/
                          opt/intel/documentation_2018/en/man/common:/opt/intel/documentation_20
                          18/en/debugger/gdb-
                          igfx/man:/opt/intel/documentation_2018/en/debugger/gdb-ia/man::
               MODULEPATH=/opt/apps/intel18/impi18_0/modulefiles:/opt/apps/intel18/modulefiles:/
                          opt/apps/xsede/modulefiles:/opt/apps/modulefiles
                  NLSPATH=/opt/intel/debugger_2018/gdb/intel64/share/locale/%l_%t/%N:/opt/intel/
                          compilers_and_libraries_2018.2.199/linux/mkl/lib/intel64/locale/%l_%t/
                          %N:/opt/intel/compilers_and_libraries_2018.2.199/linux/compiler/lib/in
                          tel64/locale/%l_%t/%N
                     PATH=/home1/08213/pkedia/anaconda3/bin:/home1/08213/pkedia/anaconda3/envs/j
                          anus/bin:/opt/apps/xalt/xalt/bin:/opt/apps/cmake/3.16.1/bin:/opt/apps/
                          intel18/python2/2.7.15/bin:/opt/apps/autotools/1.1/bin:/opt/apps/git/2
                          .24.1/bin:/opt/apps/libfabric/1.7.0/bin:/opt/apps/intel18/impi/18.0.2/
                          bin:/opt/intel/compilers_and_libraries_2018.2.199/linux/mpi/intel64/bi
                          n:/opt/intel/compilers_and_libraries_2018.2.199/linux/bin/intel64:/opt
                          /apps/gcc/6.3.0/bin:/home1/08213/pkedia/anaconda3/condabin:/usr/lib64/
                          qt-3.3/bin:/usr/local/bin:/bin:/usr/bin:/opt/dell/srvadmin/bin:.
          PKG_CONFIG_PATH=/opt/intel/compilers_and_libraries_2018.2.199/linux/mkl/bin/pkgconfig
               PYTHONPATH=/opt/apps/intel18/impi18_0/python2/2.7.15/lib/python2.7/site-packages
       REQUESTS_CA_BUNDLE=<not set>
            SSL_CERT_FILE=<not set>
     __LMOD_Priority_PATH=/opt/apps/xalt/xalt/bin:-100
__LMOD_REF_COUNT_COMPILER_PATH=/opt/apps/xalt/xalt/bin:1
   __LMOD_REF_COUNT_CPATH=/opt/intel/compilers_and_libraries_2018.2.199/linux/pstl/include:1;/op
                          t/intel/compilers_and_libraries_2018.2.199/linux/daal/include:1;/opt/i
                          ntel/compilers_and_libraries_2018.2.199/linux/tbb/include:1;/opt/intel
                          /compilers_and_libraries_2018.2.199/linux/mkl/include:1;/opt/intel/com
                          pilers_and_libraries_2018.2.199/linux/ipp/include:1
__LMOD_REF_COUNT_LD_LIBRARY_PATH=/opt/apps/intel18/python2/2.7.15/lib:1;/opt/apps/libfabric/1.7.0/lib:1
                          ;/opt/intel/compilers_and_libraries_2018.2.199/linux/mpi/intel64/lib:1
                          ;/opt/intel/debugger_2018/libipt/intel64/lib:1;/opt/intel/debugger_201
                          8/iga/lib:1;/opt/intel/compilers_and_libraries_2018.2.199/linux/daal/.
                          ./tbb/lib/intel64_lin/gcc4.4:1;/opt/intel/compilers_and_libraries_2018
                          .2.199/linux/daal/lib/intel64_lin:1;/opt/intel/compilers_and_libraries
                          _2018.2.199/linux/tbb/lib/intel64/gcc4.7:1;/opt/intel/compilers_and_li
                          braries_2018.2.199/linux/mkl/lib/intel64_lin:1;/opt/intel/compilers_an
                          d_libraries_2018.2.199/linux/compiler/lib/intel64_lin:2;/opt/intel/com
                          pilers_and_libraries_2018.2.199/linux/ipp/lib/intel64:1;/opt/intel/com
                          pilers_and_libraries_2018.2.199/linux/compiler/lib/intel64:1;/opt/apps
                          /gcc/6.3.0/lib64:1;/opt/apps/gcc/6.3.0/lib:1
__LMOD_REF_COUNT_LIBRARY_PATH=/opt/intel/compilers_and_libraries_2018.2.199/linux/daal/../tbb/lib/in
                          tel64_lin/gcc4.4:1;/opt/intel/compilers_and_libraries_2018.2.199/linux
                          /daal/lib/intel64_lin:1;/opt/intel/compilers_and_libraries_2018.2.199/
                          linux/tbb/lib/intel64/gcc4.7:1;/opt/intel/compilers_and_libraries_2018
                          .2.199/linux/mkl/lib/intel64_lin:1;/opt/intel/compilers_and_libraries_
                          2018.2.199/linux/compiler/lib/intel64_lin:1;/opt/intel/compilers_and_l
                          ibraries_2018.2.199/linux/ipp/lib/intel64:1
 __LMOD_REF_COUNT_MANPATH=/usr/local/man:1;/usr/share/man:1;/usr/X11R6/man:1;/usr/kerberos/man:1
                          ;/usr/man:1;/opt/apps/intel18/python2/2.7.15/share/man:1;/opt/apps/int
                          el18/python2/2.7.15/man:1;/opt/apps/git/2.24.1/share/man:1;/opt/apps/l
                          ibfabric/1.7.0/share/man:1;/opt/intel/compilers_and_libraries_2018.2.1
                          99/linux/mpi/man:1;/opt/intel/documentation_2018/en/man/common:1;/opt/
                          intel/documentation_2018/en/debugger/gdb-
                          igfx/man:1;/opt/intel/documentation_2018/en/debugger/gdb-ia/man:1
__LMOD_REF_COUNT_MODULEPATH=/opt/apps/intel18/impi18_0/modulefiles:1;/opt/apps/intel18/modulefiles
                          :1;/opt/apps/xsede/modulefiles:1;/opt/apps/modulefiles:1
 __LMOD_REF_COUNT_NLSPATH=/opt/intel/debugger_2018/gdb/intel64/share/locale/%l_%t/%N:1;/opt/inte
                          l/compilers_and_libraries_2018.2.199/linux/mkl/lib/intel64/locale/%l_%
                          t/%N:1;/opt/intel/compilers_and_libraries_2018.2.199/linux/compiler/li
                          b/intel64/locale/%l_%t/%N:1
    __LMOD_REF_COUNT_PATH=/opt/apps/xalt/xalt/bin:1;/opt/apps/cmake/3.16.1/bin:1;/opt/apps/intel
                          18/python2/2.7.15/bin:2;/opt/apps/autotools/1.1/bin:1;/opt/apps/git/2.
                          24.1/bin:1;/opt/apps/libfabric/1.7.0/bin:1;/opt/apps/intel18/impi/18.0
                          .2/bin:1;/opt/intel/compilers_and_libraries_2018.2.199/linux/mpi/intel
                          64/bin:1;/opt/intel/compilers_and_libraries_2018.2.199/linux/bin/intel
                          64:1;/opt/apps/gcc/6.3.0/bin:1;/home1/08213/pkedia/anaconda3/condabin:
                          1;/usr/lib64/qt-3.3/bin:1;/usr/local/bin:1;/bin:1;/usr/bin:1;/opt/dell
                          /srvadmin/bin:1;.:1
__LMOD_REF_COUNT_PYTHONPATH=/opt/apps/intel18/impi18_0/python2/2.7.15/lib/python2.7/site-
                          packages:1
         __LMOD_SET_FPATH=1

     active environment : janus
    active env location : /home1/08213/pkedia/anaconda3/envs/janus
            shell level : 1
       user config file : /home1/08213/pkedia/.condarc
 populated config files : /home1/08213/pkedia/.condarc
          conda version : 4.10.3
    conda-build version : 3.21.5
         python version : 3.9.7.final.0
       virtual packages : __linux=3.10.0=0
                          __glibc=2.17=0
                          __unix=0=0
                          __archspec=1=x86_64
       base environment : /home1/08213/pkedia/anaconda3  (writable)
      conda av data dir : /home1/08213/pkedia/anaconda3/etc/conda
  conda av metadata url : None
           channel URLs : https://repo.anaconda.com/pkgs/main/linux-64
                          https://repo.anaconda.com/pkgs/main/noarch
                          https://repo.anaconda.com/pkgs/r/linux-64
                          https://repo.anaconda.com/pkgs/r/noarch
          package cache : /home1/08213/pkedia/anaconda3/pkgs
                          /home1/08213/pkedia/.conda/pkgs
       envs directories : /home1/08213/pkedia/anaconda3/envs
                          /home1/08213/pkedia/.conda/envs
               platform : linux-64
             user-agent : conda/4.10.3 requests/2.26.0 CPython/3.9.7 Linux/3.10.0-957.5.1.el7.x86_64 centos/7.6.1810 glibc/2.17
                UID:GID : 875128:822561
             netrc file : None
           offline mode : False


An unexpected error has occurred. Conda has prepared the above report.

Traceback (most recent call last):
  File "./JANUS.py", line 215, in <module>
    mut_smi_dict = get_mutated_smiles(replace_smiles[0: len(replace_smiles)//2],  alphabet=alphabet) # Half the molecuules are to be mutated     
  File "/work2/08213/pkedia/stampede2/Janus-SarsCov/mutate_parr.py", line 266, in get_mutated_smiles
    mut_smiles = create_parr_process(chunks, alphabet, 'logP', num_random_samples=5, num_mutations=5)
  File "/work2/08213/pkedia/stampede2/Janus-SarsCov/mutate_parr.py", line 245, in create_parr_process
    item.start()
  File "/home1/08213/pkedia/anaconda3/envs/janus/lib/python3.8/multiprocessing/process.py", line 121, in start
    self._popen = self._Popen(self)
  File "/home1/08213/pkedia/anaconda3/envs/janus/lib/python3.8/multiprocessing/context.py", line 224, in _Popen
    return _default_context.get_context().Process._Popen(process_obj)
  File "/home1/08213/pkedia/anaconda3/envs/janus/lib/python3.8/multiprocessing/context.py", line 277, in _Popen
    return Popen(process_obj)
  File "/home1/08213/pkedia/anaconda3/envs/janus/lib/python3.8/multiprocessing/popen_fork.py", line 19, in __init__
    self._launch(process_obj)
  File "/home1/08213/pkedia/anaconda3/envs/janus/lib/python3.8/multiprocessing/popen_fork.py", line 70, in _launch
    self.pid = os.fork()
OSError: [Errno 12] Cannot allocate memory
Process Process-61:
Traceback (most recent call last):
  File "/home1/08213/pkedia/anaconda3/envs/janus/lib/python3.8/multiprocessing/process.py", line 315, in _bootstrap
    self.run()
  File "/home1/08213/pkedia/anaconda3/envs/janus/lib/python3.8/multiprocessing/process.py", line 108, in run
    self._target(*self._args, **self._kwargs)
  File "/work2/08213/pkedia/stampede2/Janus-SarsCov/mutate_parr.py", line 210, in calc_parr_prop
    props_collect[property_name][smile] = get_prop_material(smile, alphabet=alphabet, num_random_samples=num_random_samples, num_mutations=num_mutations)  # TODO: TESTING
  File "<string>", line 2, in __getitem__
  File "/home1/08213/pkedia/anaconda3/envs/janus/lib/python3.8/multiprocessing/managers.py", line 835, in _callmethod
    kind, result = conn.recv()
  File "/home1/08213/pkedia/anaconda3/envs/janus/lib/python3.8/multiprocessing/connection.py", line 251, in recv
    return _ForkingPickler.loads(buf.getbuffer())
  File "/home1/08213/pkedia/anaconda3/envs/janus/lib/python3.8/multiprocessing/managers.py", line 959, in RebuildProxy
    return func(token, serializer, incref=incref, **kwds)
  File "/home1/08213/pkedia/anaconda3/envs/janus/lib/python3.8/multiprocessing/managers.py", line 809, in __init__
    self._incref()
  File "/home1/08213/pkedia/anaconda3/envs/janus/lib/python3.8/multiprocessing/managers.py", line 863, in _incref
    conn = self._Client(self._token.address, authkey=self._authkey)
  File "/home1/08213/pkedia/anaconda3/envs/janus/lib/python3.8/multiprocessing/connection.py", line 502, in Client
    c = SocketClient(address)
  File "/home1/08213/pkedia/anaconda3/envs/janus/lib/python3.8/multiprocessing/connection.py", line 630, in SocketClient
    s.connect(address)
FileNotFoundError: [Errno 2] No such file or directory
Process Process-65:
Traceback (most recent call last):
  File "/home1/08213/pkedia/anaconda3/envs/janus/lib/python3.8/multiprocessing/process.py", line 315, in _bootstrap
    self.run()
  File "/home1/08213/pkedia/anaconda3/envs/janus/lib/python3.8/multiprocessing/process.py", line 108, in run
    self._target(*self._args, **self._kwargs)
  File "/work2/08213/pkedia/stampede2/Janus-SarsCov/mutate_parr.py", line 210, in calc_parr_prop
    props_collect[property_name][smile] = get_prop_material(smile, alphabet=alphabet, num_random_samples=num_random_samples, num_mutations=num_mutations)  # TODO: TESTING
  File "<string>", line 2, in __getitem__
  File "/home1/08213/pkedia/anaconda3/envs/janus/lib/python3.8/multiprocessing/managers.py", line 835, in _callmethod
    kind, result = conn.recv()
  File "/home1/08213/pkedia/anaconda3/envs/janus/lib/python3.8/multiprocessing/connection.py", line 251, in recv
    return _ForkingPickler.loads(buf.getbuffer())
  File "/home1/08213/pkedia/anaconda3/envs/janus/lib/python3.8/multiprocessing/managers.py", line 959, in RebuildProxy
    return func(token, serializer, incref=incref, **kwds)
  File "/home1/08213/pkedia/anaconda3/envs/janus/lib/python3.8/multiprocessing/managers.py", line 809, in __init__
    self._incref()
  File "/home1/08213/pkedia/anaconda3/envs/janus/lib/python3.8/multiprocessing/managers.py", line 863, in _incref
    conn = self._Client(self._token.address, authkey=self._authkey)
  File "/home1/08213/pkedia/anaconda3/envs/janus/lib/python3.8/multiprocessing/connection.py", line 508, in Client
    answer_challenge(c, authkey)
  File "/home1/08213/pkedia/anaconda3/envs/janus/lib/python3.8/multiprocessing/connection.py", line 752, in answer_challenge
    message = connection.recv_bytes(256)         # reject large message
  File "/home1/08213/pkedia/anaconda3/envs/janus/lib/python3.8/multiprocessing/connection.py", line 216, in recv_bytes
    buf = self._recv_bytes(maxlength)
  File "/home1/08213/pkedia/anaconda3/envs/janus/lib/python3.8/multiprocessing/connection.py", line 414, in _recv_bytes
    buf = self._recv(4)
  File "/home1/08213/pkedia/anaconda3/envs/janus/lib/python3.8/multiprocessing/connection.py", line 379, in _recv
    chunk = read(handle, remaining)
ConnectionResetError: [Errno 104] Connection reset by peer
Process Process-68:
Traceback (most recent call last):
  File "/home1/08213/pkedia/anaconda3/envs/janus/lib/python3.8/multiprocessing/managers.py", line 827, in _callmethod
    conn = self._tls.connection
AttributeError: 'ForkAwareLocal' object has no attribute 'connection'

During handling of the above exception, another exception occurred:

Traceback (most recent call last):
  File "/home1/08213/pkedia/anaconda3/envs/janus/lib/python3.8/multiprocessing/process.py", line 315, in _bootstrap
    self.run()
  File "/home1/08213/pkedia/anaconda3/envs/janus/lib/python3.8/multiprocessing/process.py", line 108, in run
    self._target(*self._args, **self._kwargs)
  File "/work2/08213/pkedia/stampede2/Janus-SarsCov/mutate_parr.py", line 210, in calc_parr_prop
    props_collect[property_name][smile] = get_prop_material(smile, alphabet=alphabet, num_random_samples=num_random_samples, num_mutations=num_mutations)  # TODO: TESTING
  File "<string>", line 2, in __getitem__
  File "/home1/08213/pkedia/anaconda3/envs/janus/lib/python3.8/multiprocessing/managers.py", line 831, in _callmethod
    self._connect()
  File "/home1/08213/pkedia/anaconda3/envs/janus/lib/python3.8/multiprocessing/managers.py", line 818, in _connect
    conn = self._Client(self._token.address, authkey=self._authkey)
  File "/home1/08213/pkedia/anaconda3/envs/janus/lib/python3.8/multiprocessing/connection.py", line 502, in Client
    c = SocketClient(address)
  File "/home1/08213/pkedia/anaconda3/envs/janus/lib/python3.8/multiprocessing/connection.py", line 630, in SocketClient
    s.connect(address)
FileNotFoundError: [Errno 2] No such file or directory
Process Process-66:
Traceback (most recent call last):
  File "/home1/08213/pkedia/anaconda3/envs/janus/lib/python3.8/multiprocessing/managers.py", line 827, in _callmethod
    conn = self._tls.connection
AttributeError: 'ForkAwareLocal' object has no attribute 'connection'

During handling of the above exception, another exception occurred:

Traceback (most recent call last):
  File "/home1/08213/pkedia/anaconda3/envs/janus/lib/python3.8/multiprocessing/process.py", line 315, in _bootstrap
    self.run()
  File "/home1/08213/pkedia/anaconda3/envs/janus/lib/python3.8/multiprocessing/process.py", line 108, in run
    self._target(*self._args, **self._kwargs)
  File "/work2/08213/pkedia/stampede2/Janus-SarsCov/mutate_parr.py", line 210, in calc_parr_prop
    props_collect[property_name][smile] = get_prop_material(smile, alphabet=alphabet, num_random_samples=num_random_samples, num_mutations=num_mutations)  # TODO: TESTING
  File "<string>", line 2, in __getitem__
  File "/home1/08213/pkedia/anaconda3/envs/janus/lib/python3.8/multiprocessing/managers.py", line 831, in _callmethod
    self._connect()
  File "/home1/08213/pkedia/anaconda3/envs/janus/lib/python3.8/multiprocessing/managers.py", line 818, in _connect
    conn = self._Client(self._token.address, authkey=self._authkey)
  File "/home1/08213/pkedia/anaconda3/envs/janus/lib/python3.8/multiprocessing/connection.py", line 502, in Client
    c = SocketClient(address)
  File "/home1/08213/pkedia/anaconda3/envs/janus/lib/python3.8/multiprocessing/connection.py", line 630, in SocketClient
    s.connect(address)
FileNotFoundError: [Errno 2] No such file or directory
Process Process-67:
Traceback (most recent call last):
  File "/home1/08213/pkedia/anaconda3/envs/janus/lib/python3.8/multiprocessing/managers.py", line 827, in _callmethod
    conn = self._tls.connection
AttributeError: 'ForkAwareLocal' object has no attribute 'connection'

During handling of the above exception, another exception occurred:

Traceback (most recent call last):
  File "/home1/08213/pkedia/anaconda3/envs/janus/lib/python3.8/multiprocessing/process.py", line 315, in _bootstrap
    self.run()
  File "/home1/08213/pkedia/anaconda3/envs/janus/lib/python3.8/multiprocessing/process.py", line 108, in run
    self._target(*self._args, **self._kwargs)
  File "/work2/08213/pkedia/stampede2/Janus-SarsCov/mutate_parr.py", line 210, in calc_parr_prop
    props_collect[property_name][smile] = get_prop_material(smile, alphabet=alphabet, num_random_samples=num_random_samples, num_mutations=num_mutations)  # TODO: TESTING
  File "<string>", line 2, in __getitem__
  File "/home1/08213/pkedia/anaconda3/envs/janus/lib/python3.8/multiprocessing/managers.py", line 831, in _callmethod
    self._connect()
  File "/home1/08213/pkedia/anaconda3/envs/janus/lib/python3.8/multiprocessing/managers.py", line 818, in _connect
    conn = self._Client(self._token.address, authkey=self._authkey)
  File "/home1/08213/pkedia/anaconda3/envs/janus/lib/python3.8/multiprocessing/connection.py", line 502, in Client
    c = SocketClient(address)
  File "/home1/08213/pkedia/anaconda3/envs/janus/lib/python3.8/multiprocessing/connection.py", line 630, in SocketClient
    s.connect(address)
FileNotFoundError: [Errno 2] No such file or directory
Process Process-64:
Traceback (most recent call last):
  File "/home1/08213/pkedia/anaconda3/envs/janus/lib/python3.8/multiprocessing/managers.py", line 827, in _callmethod
    conn = self._tls.connection
AttributeError: 'ForkAwareLocal' object has no attribute 'connection'

During handling of the above exception, another exception occurred:

Traceback (most recent call last):
  File "/home1/08213/pkedia/anaconda3/envs/janus/lib/python3.8/multiprocessing/process.py", line 315, in _bootstrap
    self.run()
  File "/home1/08213/pkedia/anaconda3/envs/janus/lib/python3.8/multiprocessing/process.py", line 108, in run
    self._target(*self._args, **self._kwargs)
  File "/work2/08213/pkedia/stampede2/Janus-SarsCov/mutate_parr.py", line 210, in calc_parr_prop
    props_collect[property_name][smile] = get_prop_material(smile, alphabet=alphabet, num_random_samples=num_random_samples, num_mutations=num_mutations)  # TODO: TESTING
  File "<string>", line 2, in __getitem__
  File "/home1/08213/pkedia/anaconda3/envs/janus/lib/python3.8/multiprocessing/managers.py", line 831, in _callmethod
    self._connect()
  File "/home1/08213/pkedia/anaconda3/envs/janus/lib/python3.8/multiprocessing/managers.py", line 818, in _connect
    conn = self._Client(self._token.address, authkey=self._authkey)
  File "/home1/08213/pkedia/anaconda3/envs/janus/lib/python3.8/multiprocessing/connection.py", line 502, in Client
    c = SocketClient(address)
  File "/home1/08213/pkedia/anaconda3/envs/janus/lib/python3.8/multiprocessing/connection.py", line 630, in SocketClient
    s.connect(address)
FileNotFoundError: [Errno 2] No such file or directory
